Workbook

Sheet Ingredientes
B4: Ingredientes | C4: Embalagem Fechada (g) | D4: Valor Fechado
B5: ='Custo Unitário'!B70 -> Caldo Verde | C5: 1000 | D5: 25
B6: Tomate | C6: 1000 | D6: =

Sheet Custo Unitário
B4: Frango | C4: Ingredientes | D4: Quantidade (g) | E4: Quantidade da Embalagem (g) | F4: Preço Fechado | G4: Custo Proporcional
E5: =IF(C5="","",VLOOKUP(C5,Ingredientes!B:C,2,0)) | F5: =IF(C5="","",VLOOKUP(C5,Ingredientes!B:E,3,0)) | G5: =IF(C5="","",F5/E5*D5) | I5: Custo por unidade | J5: =IF(G5="","",SUM(G5:G18))
E6: =IF(C6="","",VLOOKUP(C6,Ingredientes!B:C,2,0)) | F6: =IF(C6="","",VLOOKUP(C6,Ingredientes!B:E,3,0)) | G6: =IF(C6="","",F6/E6*D6) | I6: Preço de venda
E7: =IF(C7="","",VLOOKUP(C7,Ingredientes!B:C,2,0)) | F7: =IF(C7="","",VLOOKUP(C7,Ingredientes!B:E,3,0)) | G7: =IF(C7="","",F7/E7*D7) | I7: Lucro | J7: =IF(J6="","",J6-J5)
E8: =IF(C8="","",VLOOKUP(C8,Ingredientes!B:C,2,0)) | F8: =IF(C8="","",VLOOKUP(C8,Ingredientes!B:E,3,0)) | G8: =IF(C8="","",F8/E8*D8) | I8: Lucro % | J8: =IF(J7="","",J7/J5)
E9: =IF(C9="","",VLOOKUP(C9,Ingredientes!B:C,2,0)) | F9: =IF(C9="","",VLOOKUP(C9,Ingredientes!B:E,3,0)) | G9: =IF(C9="","",F9/E9*D9) | I9: Meta %
E10: =IF(C10="","",VLOOKUP(C10,Ingredientes!B:C,2,0)) | F10: =IF(C10="","",VLOOKUP(C10,Ingredientes!B:E,3,0)) | G10: =IF(C10="","",F10/E10*D10) | I10: Valor a ser vendido estimado | J10: =IF(J9="","",(J5*J9)+J5)
E11: =IF(C11="","",VLOOKUP(C11,Ingredientes!B:C,2,0)) | F11: =IF(C11="","",VLOOKUP(C11,Ingredientes!B:E,3,0)) | G11: =IF(C11="","",F11/E11*D11)
E12: =IF(C12="","",VLOOKUP(C12,Ingredientes!B:C,2,0)) | F12: =IF(C12="","",VLOOKUP(C12,Ingredientes!B:E,3,0)) | G12: =IF(C12="","",F12/E12*D12)
E13: =IF(C13="","",VLOOKUP(C13,Ingredientes!B:C,2,0)) | F13: =IF(C13="","",VLOOKUP(C13,Ingredientes!B:E,3,0)) | G13: =IF(C13="","",F13/E13*D13)
E14: =IF(C14="","",VLOOKUP(C14,Ingredientes!B:C,2,0)) | F14: =IF(C14="","",VLOOKUP(C14,Ingredientes!B:E,3,0)) | G14: =IF(C14="","",F14/E14*D14)
E15: =IF(C15="","",VLOOKUP(C15,Ingredientes!B:C,2,0)) | F15: =IF(C15="","",VLOOKUP(C15,Ingredientes!B:E,3,0)) | G15: =IF(C15="","",F15/E15*D15)
E16: =IF(C16="","",VLOOKUP(C16,Ingredientes!B:C,2,0)) | F16: =IF(C16="","",VLOOKUP(C16,Ingredientes!B:E,3,0)) | G16: =IF(C16="","",F16/E16*D16)
E17: =IF(C17="","",VLOOKUP(C17,Ingredientes!B:C,2,0)) | F17: =IF(C17="","",VLOOKUP(C17,Ingredientes!B:E,3,0)) | G17: =IF(C17="","",F17/E17*D17)
E18: =IF(C18="","",VLOOKUP(C18,Ingredientes!B:C,2,0)) | F18: =IF(C18="","",VLOOKUP(C18,Ingredientes!B:E,3,0)) | G18: =IF(C18="","",F18/E18*D18)
B20: Frango Rústico | C20: Ingredientes | D20: Quantidade | E20: Quantidade da Embalagem | F20: Preço Fechado | G20: Custo Proporcional
E21: =IF(C21="","",VLOOKUP(C21,Ingredientes!B:C,2,0)) | F21: =IF(C21="","",VLOOKUP(C21,Ingredientes!B:E,3,0)) | G21: =IF(C21="","",F21/E21*D21) | I21: Custo por unidade | J21: =IF(G21="","",SUM(G21:G34))
E22: =IF(C22="","",VLOOKUP(C22,Ingredientes!B:C,2,0)) | F22: =IF(C22="","",VLOOKUP(C22,Ingredientes!B:E,3,0)) | G22: =IF(C22="","",F22/E22*D22) | I22: Preço de venda
E23: =IF(C23="","",VLOOKUP(C23,Ingredientes!B:C,2,0)) | F23: =IF(C23="","",VLOOKUP(C23,Ingredientes!B:E,3,0)) | G23: =IF(C23="","",F23/E23*D23) | I23: Lucro | J23: =IF(J22="","",J22-J21)
E24: =IF(C24="","",VLOOKUP(C24,Ingredientes!B:C,2,0)) | F24: =IF(C24="","",VLOOKUP(C24,Ingredientes!B:E,3,0)) | G24: =IF(C24="","",F24/E24*D24) | I24: Lucro % | J24: =IF(J23="","",J23/J21)
E25: =IF(C25="","",VLOOKUP(C25,Ingredientes!B:C,2,0)) | F25: =IF(C25="","",VLOOKUP(C25,Ingredientes!B:E,3,0)) | G25: =IF(C25="","",F25/E25*D25) | I25: Meta %
E26: =IF(C26="","",VLOOKUP(C26,Ingredientes!B:C,2,0)) | F26: =IF(C26="","",VLOOKUP(C26,Ingredientes!B:E,3,0)) | G26: =IF(C26="","",F26/E26*D26) | I26: Valor a ser vendido estimado | J26: =IF(J25="","",(J21*J25)+J21)
E27: =IF(C27="","",VLOOKUP(C27,Ingredientes!B:C,2,0)) | F27: =IF(C27="","",VLOOKUP(C27,Ingredientes!B:E,3,0)) | G27: =IF(C27="","",F27/E27*D27)
E28: =IF(C28="","",VLOOKUP(C28,Ingredientes!B:C,2,0)) | F28: =IF(C28="","",VLOOKUP(C28,Ingredientes!B:E,3,0)) | G28: =IF(C28="","",F28/E28*D28)
E29: =IF(C29="","",VLOOKUP(C29,Ingredientes!B:C,2,0)) | F29: =IF(C29="","",VLOOKUP(C29,Ingredientes!B:E,3,0)) | G29: =IF(C29="","",F29/E29*D29)
E30: =IF(C30="","",VLOOKUP(C30,Ingredientes!B:C,2,0)) | F30: =IF(C30="","",VLOOKUP(C30,Ingredientes!B:E,3,0)) | G30: =IF(C30="","",F30/E30*D30)
E31: =IF(C31="","",VLOOKUP(C31,Ingredientes!B:C,2,0)) | F31: =IF(C31="","",VLOOKUP(C31,Ingredientes!B:E,3,0)) | G31: =IF(C31="","",F31/E31*D31)
E32: =IF(C32="","",VLOOKUP(C32,Ingredientes!B:C,2,0)) | F32: =IF(C32="","",VLOOKUP(C32,Ingredientes!B:E,3,0)) | G32: =IF(C32="","",F32/E32*D32)
E33: =IF(C33="","",VLOOKUP(C33,Ingredientes!B:C,2,0)) | F33: =IF(C33="","",VLOOKUP(C33,Ingredientes!B:E,3,0)) | G33: =IF(C33="","",F33/E33*D33)
E34: =IF(C34="","",VLOOKUP(C34,Ingredientes!B:C,2,0)) | F34: =IF(C34="","",VLOOKUP(C34,Ingredientes!B:E,3,0)) | G34: =IF(C34="","",F34/E34*D34)
E35: =IF(C35="","",VLOOKUP(C35,Ingredientes!B:C,2,0)) | F35: =IF(C35="","",VLOOKUP(C35,Ingredientes!B:E,3,0)) | G35: =IF(C35="","",F35/E35*D35)
B37: Carne Louca | C37: Ingredientes | D37: Quantidade | E37: Quantidade da Embalagem | F37: Preço Fechado | G37: Custo Proporcional
E38: =IF(C38="","",VLOOKUP(C38,Ingredientes!B:C,2,0)) | F38: =IF(C38="","",VLOOKUP(C38,Ingredientes!B:E,3,0)) | G38: =IF(C38="","",F38/E38*D38) | I38: Custo por unidade | J38: =IF(G38="","",SUM(G38:G51))
E39: =IF(C39="","",VLOOKUP(C39,Ingredientes!B:C,2,0)) | F39: =IF(C39="","",VLOOKUP(C39,Ingredientes!B:E,3,0)) | G39: =IF(C39="","",F39/E39*D39) | I39: Preço de venda
E40: =IF(C40="","",VLOOKUP(C40,Ingredientes!B:C,2,0)) | F40: =IF(C40="","",VLOOKUP(C40,Ingredientes!B:E,3,0)) | G40: =IF(C40="","",F40/E40*D40) | I40: Lucro | J40: =IF(J39="","",J39-J38)
E41: =IF(C41="","",VLOOKUP(C41,Ingredientes!B:C,2,0)) | F41: =IF(C41="","",VLOOKUP(C41,Ingredientes!B:E,3,0)) | G41: =IF(C41="","",F41/E41*D41) | I41: Lucro % | J41: =IF(J40="","",J40/J38)
E42: =IF(C42="","",VLOOKUP(C42,Ingredientes!B:C,2,0)) | F42: =IF(C42="","",VLOOKUP(C42,Ingredientes!B:E,3,0)) | G42: =IF(C42="","",F42/E42*D42) | I42: Meta %
E43: =IF(C43="","",VLOOKUP(C43,Ingredientes!B:C,2,0)) | F43: =IF(C43="","",VLOOKUP(C43,Ingredientes!B:E,3,0)) | G43: =IF(C43="","",F43/E43*D43) | I43: Valor a ser vendido estimado | J43: =IF(J42="","",(J38*J42)+J38)
E44: =IF(C44="","",VLOOKUP(C44,Ingredientes!B:C,2,0)) | F44: =IF(C44="","",VLOOKUP(C44,Ingredientes!B:E,3,0)) | G44: =IF(C44="","",F44/E44*D44)
E45: =IF(C45="","",VLOOKUP(C45,Ingredientes!B:C,2,0)) | F45: =IF(C45="","",VLOOKUP(C45,Ingredientes!B:E,3,0)) | G45: =IF(C45="","",F45/E45*D45)
...
